Workbook

Sheet Cover
B2: DAILY EXPENSE TRACKER
B3: Pencatatan Pengeluaran Harian - Mei 2026
B5: Catat setiap pengeluaran harian Anda untuk memantau keuangan dengan lebih detail. Setiap transaksi tercatat dengan tanggal, kategori, dan jumlah.
B9: Fitur Utama:
B10: ✓ Input pengeluaran harian per tanggal
B11: ✓ Kategorisasi otomatis (Makanan, Transportasi, dll)
B12: ✓ Total harian & bulanan otomatis
B13: ✓ Analisis pengeluaran per kategori
B14: ✓ Grafik trend harian dan breakdown kategori
B15: ✓ Highlight akhir pekan untuk perencanaan
B17: Daftar Sheet:
B18: Sheet | C18: Deskripsi
B19: Cover | C19: Halaman utama dan informasi
B20: Input Harian | C20: Input pengeluaran harian per tanggal & kategori
B21: Rekap Harian | C21: Ringkasan total pengeluaran per hari
B22: Analisis Kategori | C22: Breakdown pengeluaran per kategori
B23: Grafik | C23: Visualisasi data pengeluaran
B25: Tips Penggunaan:
B26: 1. Buka sheet 'Input Harian' dan masukkan setiap pengeluaran
B27: 2. Pilih kategori dari dropdown yang tersedia
B28: 3. Cek 'Rekap Harian' untuk total per hari
B29: 4. Lihat 'Analisis Kategori' untuk breakdown
B30: 5. Pantau grafik untuk trend pengeluaran

Sheet Input Harian
B2: INPUT PENGELUARAN HARIAN - APRIL 2026
B4: Tanggal | C4: Hari | D4: Kategori | E4: Keterangan | F4: Jumlah (Rp) | G4: Total Harian
B5: 12 | C5: Selasa | D5: Lainnya | E5: Parkir UIN | F5: 1000 | G5: =SUM(F5:F9) -> 41000
D6: Makanan | E6: Nasi Ayam | F6: 13000
D7: Makanan | E7: Telor Gulung | F7: 5000
D8: Transportasi | E8: Bensin Migi | F8: 22000
B10: 13 | C10: Rabu | D10: Makanan | E10: Nasi Kuning + Nasi Ayam +Warteg | F10: 41000 | G10: =SUM(F10:F14) -> 96000
D11: Makanan | E11: Kopi + Pulpy Orange | F11: 18000
D12: Makanan | E12: C1000 | F12: 8000
D13: Lainnya | E13: Parkir UIN + PONRAN | F13: 7000
D14: Transportasi | E14: Bensin | F14: 22000
B15: 14 | C15: Kamis | D15: Makanan | E15: Nasi Kuning | F15: 12000 | G15: =SUM(F15:F19) -> 33000
D16: Transportasi | E16: Bensin | F16: 15000
D17: Lainnya | E17: Parkir Blok M | F17: 6000
B20: 15 | C20: Jumat | G20: =SUM(F20:F24) -> 0
B25: 16 | C25: Sabtu | G25: =SUM(F25:F29) -> 0
B30: 17 | C30: Minggu | D30: Makanan | E30: Gacoan | F30: 27000 | G30: =SUM(F30:F34) -> 27000
B35: 18 | C35: Senin | D35: Makanan | E35: Bubur Ayam | F35: 12000 | G35: =SUM(F35:F39) -> 12000
B40: 19 | C40: Selasa | D40: Transportasi | E40: Bensin | F40: 20000 | G40: =SUM(F40:F44) -> 114500
D41: Hiburan | E41: Kue | F41: 32500
D42: Hiburan | E42: Lukis-Lukis | F42: 6000
D43: Makanan | E43: Nasi Ayam + VIT + Susu | F43: 50000
D44: Lainnya | E44: Parkir | F44: 6000
B45: 20 | C45: Rabu | D45: Makanan | E45: Nasi Ayam | F45: 15000 | G45: =SUM(F45:F49) -> 68000
D46: Transportasi | E46: Bensin | F46: 20000
D47: Lainnya | E47: Uin Kelawai | F47: 4000
D48: Makanan | E48: Nasi Ayam Popcorn | F48: 20000
D49: Belanja | E49: Gunting Kuku | F49: 9000
B50: 21 | C50: Kamis | G50: =SUM(F50:F54) -> 0
B55: 22 | C55: Jumat | D55: Transportasi | E55: Bensin | F55: 10000 | G55: =SUM(F55:F59) -> 27000
D56: Makanan | E56: Nasi Ayam | F56: 15000
D57: Lainnya | E57: Parkir | F57: 2000
B60: 23 | C60: Sabtu | D60: Makanan | E60: Good Day | F60: 4000 | G60: =SUM(F60:F64) -> 4000
B65: 24 | C65: Minggu | D65: Transportasi | E65: Bensin | F65: 20000 | G65: =SUM(F65:F69) -> 71000
D66: Makanan | E66: kopi dan susu, nasi ayam | F66: 27000
D67: Lainnya | E67: parkir | F67: 4000
D68: Makanan | E68: silverqueen | F68: 20000
B70: 25 | C70: Senin | D70: Makanan | E70: Nasi Ayam | F70: 35000 | G70: =SUM(F70:F74) -> 49000
D71: Transportasi | E71: Bensin | F71: 10000
D72: Lainnya | E72: parkir | F72: 4000
...

Sheet Rekap Harian
B2: REKAP PENGELUARAN HARIAN - Mei 2026
B4: Tanggal | C4: Hari | D4: Makanan | E4: Transportasi | F4: Belanja | G4: Hiburan | H4: Tagihan | I4: Lainnya | J4: Total Harian
B5: 12 | C5: Selasa | D5: {=SUMIFS('Input Harian'!$F$5:$F$104, IF('Input Harian'!$B$5:$B$104="", LOOKUP(ROW('Input Harian'!$B$5:$B$104), ROW('Input Harian'!$B$5:$B$104)/('Input Harian'!$B$5:$B$104<>""), 'Input Harian'!$B$5:$B$104), 'Input Harian'!$B$5:$B$104), $B5, 'Input Harian'!$D$5:$D$104,"*"&D$4&"*")} -> 18000 | E5: {=SUMIFS('Input Harian'!$F$5:$F$104, IF('Input Harian'!$B$5:$B$104="", LOOKUP(ROW('Input Harian'!$B$5:$B$104), ROW('Input Harian'!$B$5:$B$104)/('Input Harian'!$B$5:$B$104<>""), 'Input Harian'!$B$5:$B$104), 'Input Harian'!$B$5:$B$104), $B5, 'Input Harian'!$D$5:$D$104,"*"&E$4&"*")} -> 22000 | F5: =SUMIFS('Input Harian'!$F$5:$F$104,'Input Harian'!$B$5:$B$104,B5,'Input Harian'!$D$5:$D$104,"Belanja") -> 0 | G5: =SUMIFS('Input Harian'!$F$5:$F$104,'Input Harian'!$B$5:$B$104,B5,'Input Harian'!$D$5:$D$104,"Hiburan") -> 0 | H5: =SUMIFS('Input Harian'!$F$5:$F$104,'Input Harian'!$B$5:$B$104,B5,'Input Harian'!$D$5:$D$104,"Tagihan (Listrik/Air/Internet)") -> 0 | I5: =SUMIFS('Input Harian'!$F$5:$F$104,'Input Harian'!$B$5:$B$104,B5,'Input Harian'!$D$5:$D$104,"Lainnya") -> 1000 | J5: =SUM(D5:I5) -> 41000
B6: 13 | C6: Rabu | D6: {=SUMIFS('Input Harian'!$F$5:$F$104, IF('Input Harian'!$B$5:$B$104="", LOOKUP(ROW('Input Harian'!$B$5:$B$104), ROW('Input Harian'!$B$5:$B$104)/('Input Harian'!$B$5:$B$104<>""), 'Input Harian'!$B$5:$B$104), 'Input Harian'!$B$5:$B$104), $B6, 'Input Harian'!$D$5:$D$104,"*"&D$4&"*")} -> 67000 | E6: {=SUMIFS('Input Harian'!$F$5:$F$104, IF('Input Harian'!$B$5:$B$104="", LOOKUP(ROW('Input Harian'!$B$5:$B$104), ROW('Input Harian'!$B$5:$B$104)/('Input Harian'!$B$5:$B$104<>""), 'Input Harian'!$B$5:$B$104), 'Input Harian'!$B$5:$B$104), $B6, 'Input Harian'!$D$5:$D$104,"*"&E$4&"*")} -> 22000 | F6: =SUMIFS('Input Harian'!$F$5:$F$104,'Input Harian'!$B$5:$B$104,B6,'Input Harian'!$D$5:$D$104,"Belanja") -> 0 | G6: =SUMIFS('Input Harian'!$F$5:$F$104,'Input Harian'!$B$5:$B$104,B6,'Input Harian'!$D$5:$D$104,"Hiburan") -> 0 | H6: =SUMIFS('Input Harian'!$F$5:$F$104,'Input Harian'!$B$5:$B$104,B6,'Input Harian'!$D$5:$D$104,"Tagihan (Listrik/Air/Internet)") -> 0 | I6: =SUMIFS('Input Harian'!$F$5:$F$104,'Input Harian'!$B$5:$B$104,B6,'Input Harian'!$D$5:$D$104,"Lainnya") -> 0 | J6: =SUM(D6:I6) -> 89000
B7: 14 | C7: Kamis | D7: {=SUMIFS('Input Harian'!$F$5:$F$104, IF('Input Harian'!$B$5:$B$104="", LOOKUP(ROW('Input Harian'!$B$5:$B$104), ROW('Input Harian'!$B$5:$B$104)/('Input Harian'!$B$5:$B$104<>""), 'Input Harian'!$B$5:$B$104), 'Input Harian'!$B$5:$B$104), $B7, 'Input Harian'!$D$5:$D$104,"*"&D$4&"*")} -> 12000 | E7: {=SUMIFS('Input Harian'!$F$5:$F$104, IF('Input Harian'!$B$5:$B$104="", LOOKUP(ROW('Input Harian'!$B$5:$B$104), ROW('Input Harian'!$B$5:$B$104)/('Input Harian'!$B$5:$B$104<>""), 'Input Harian'!$B$5:$B$104), 'Input Harian'!$B$5:$B$104), $B7, 'Input Harian'!$D$5:$D$104,"*"&E$4&"*")} -> 15000 | F7: =SUMIFS('Input Harian'!$F$5:$F$104,'Input Harian'!$B$5:$B$104,B7,'Input Harian'!$D$5:$D$104,"Belanja") -> 0 | G7: =SUMIFS('Input Harian'!$F$5:$F$104,'Input Harian'!$B$5:$B$104,B7,'Input Harian'!$D$5:$D$104,"Hiburan") -> 0 | H7: =SUMIFS('Input Harian'!$F$5:$F$104,'Input Harian'!$B$5:$B$104,B7,'Input Harian'!$D$5:$D$104,"Tagihan (Listrik/Air/Internet)") -> 0 | I7: =SUMIFS('Input Harian'!$F$5:$F$104,'Input Harian'!$B$5:$B$104,B7,'Input Harian'!$D$5:$D$104,"Lainnya") -> 0 | J7: =SUM(D7:I7) -> 27000
B8: 15 | C8: Jumat | D8: {=SUMIFS('Input Harian'!$F$5:$F$104, IF('Input Harian'!$B$5:$B$104="", LOOKUP(ROW('Input Harian'!$B$5:$B$104), ROW('Input Harian'!$B$5:$B$104)/('Input Harian'!$B$5:$B$104<>""), 'Input Harian'!$B$5:$B$104), 'Input Harian'!$B$5:$B$104), $B8, 'Input Harian'!$D$5:$D$104,"*"&D$4&"*")} -> 0 | E8: {=SUMIFS('Input Harian'!$F$5:$F$104, IF('Input Harian'!$B$5:$B$104="", LOOKUP(ROW('Input Harian'!$B$5:$B$104), ROW('Input Harian'!$B$5:$B$104)/('Input Harian'!$B$5:$B$104<>""), 'Input Harian'!$B$5:$B$104), 'Input Harian'!$B$5:$B$104), $B8, 'Input Harian'!$D$5:$D$104,"*"&E$4&"*")} -> 0 | F8: {=SUMIFS('Input Harian'!$F$5:$F$104, IF('Input Harian'!$B$5:$B$104="", LOOKUP(ROW('Input Harian'!$B$5:$B$104), ROW('Input Harian'!$B$5:$B$104)/('Input Harian'!$B$5:$B$104<>""), 'Input Harian'!$B$5:$B$104), 'Input Harian'!$B$5:$B$104), $B8, 'Input Harian'!$D$5:$D$104,"*Belanja*")} -> 0 | G8: {=SUMIFS('Input Harian'!$F$5:$F$104, IF('Input Harian'!$B$5:$B$104="", LOOKUP(ROW('Input Harian'!$B$5:$B$104), ROW('Input Harian'!$B$5:$B$104)/('Input Harian'!$B$5:$B$104<>""), 'Input Harian'!$B$5:$B$104), 'Input Harian'!$B$5:$B$104), $B8, 'Input Harian'!$D$5:$D$104,"*"&G$4&"*")} -> 0 | H8: {=SUMIFS('Input Harian'!$F$5:$F$104, IF('Input Harian'!$B$5:$B$104="", LOOKUP(ROW('Input Harian'!$B$5:$B$104), ROW('Input Harian'!$B$5:$B$104)/('Input Harian'!$B$5:$B$104<>""), 'Input Harian'!$B$5:$B$104), 'Input Harian'!$B$5:$B$104), $B8, 'Input Harian'!$D$5:$D$104,"*"&H$4&"*")} -> 0 | I8: {=SUMIFS('Input Harian'!$F$5:$F$104, IF('Input Harian'!$B$5:$B$104="", LOOKUP(ROW('Input Harian'!$B$5:$B$104), ROW('Input Harian'!$B$5:$B$104)/('Input Harian'!$B$5:$B$104<>""), 'Input Harian'!$B$5:$B$104), 'Input Harian'!$B$5:$B$104), $B8, 'Input Harian'!$D$5:$D$104,"*"&I$4&"*")} -> 0 | J8: =SUM(D8:I8) -> 0
B9: 16 | C9: Sabtu | D9: {=SUMIFS('Input Harian'!$F$5:$F$104, IF('Input Harian'!$B$5:$B$104="", LOOKUP(ROW('Input Harian'!$B$5:$B$104), ROW('Input Harian'!$B$5:$B$104)/('Input Harian'!$B$5:$B$104<>""), 'Input Harian'!$B$5:$B$104), 'Input Harian'!$B$5:$B$104), $B9, 'Input Harian'!$D$5:$D$104,"*"&D$4&"*")} -> 0 | E9: {=SUMIFS('Input Harian'!$F$5:$F$104, IF('Input Harian'!$B$5:$B$104="", LOOKUP(ROW('Input Harian'!$B$5:$B$104), ROW('Input Harian'!$B$5:$B$104)/('Input Harian'!$B$5:$B$104<>""), 'Input Harian'!$B$5:$B$104), 'Input Harian'!$B$5:$B$104), $B9, 'Input Harian'!$D$5:$D$104,"*"&E$4&"*")} -> 0 | F9: {=SUMIFS('Input Harian'!$F$5:$F$104, IF('Input Harian'!$B$5:$B$104="", LOOKUP(ROW('Input Harian'!$B$5:$B$104), ROW('Input Harian'!$B$5:$B$104)/('Input Harian'!$B$5:$B$104<>""), 'Input Harian'!$B$5:$B$104), 'Input Harian'!$B$5:$B$104), $B9, 'Input Harian'!$D$5:$D$104,"*Belanja*")} -> 0 | G9: {=SUMIFS('Input Harian'!$F$5:$F$104, IF('Input Harian'!$B$5:$B$104="", LOOKUP(ROW('Input Harian'!$B$5:$B$104), ROW('Input Harian'!$B$5:$B$104)/('Input Harian'!$B$5:$B$104<>""), 'Input Harian'!$B$5:$B$104), 'Input Harian'!$B$5:$B$104), $B9, 'Input Harian'!$D$5:$D$104,"*"&G$4&"*")} -> 0 | H9: {=SUMIFS('Input Harian'!$F$5:$F$104, IF('Input Harian'!$B$5:$B$104="", LOOKUP(ROW('Input Harian'!$B$5:$B$104), ROW('Input Harian'!$B$5:$B$104)/('Input Harian'!$B$5:$B$104<>""), 'Input Harian'!$B$5:$B$104), 'Input Harian'!$B$5:$B$104), $B9, 'Input Harian'!$D$5:$D$104,"*"&H$4&"*")} -> 0 | I9: {=SUMIFS('Input Harian'!$F$5:$F$104, IF('Input Harian'!$B$5:$B$104="", LOOKUP(ROW('Input Harian'!$B$5:$B$104), ROW('Input Harian'!$B$5:$B$104)/('Input Harian'!$B$5:$B$104<>""), 'Input Harian'!$B$5:$B$104), 'Input Harian'!$B$5:$B$104), $B9, 'Input Harian'!$D$5:$D$104,"*"&I$4&"*")} -> 0 | J9: =SUM(D9:I9) -> 0
B10: 17 | C10: Minggu | D10: {=SUMIFS('Input Harian'!$F$5:$F$104, IF('Input Harian'!$B$5:$B$104="", LOOKUP(ROW('Input Harian'!$B$5:$B$104), ROW('Input Harian'!$B$5:$B$104)/('Input Harian'!$B$5:$B$104<>""), 'Input Harian'!$B$5:$B$104), 'Input Harian'!$B$5:$B$104), $B10, 'Input Harian'!$D$5:$D$104,"*"&D$4&"*")} -> 27000 | E10: {=SUMIFS('Input Harian'!$F$5:$F$104, IF('Input Harian'!$B$5:$B$104="", LOOKUP(ROW('Input Harian'!$B$5:$B$104), ROW('Input Harian'!$B$5:$B$104)/('Input Harian'!$B$5:$B$104<>""), 'Input Harian'!$B$5:$B$104), 'Input Harian'!$B$5:$B$104), $B10, 'Input Harian'!$D$5:$D$104,"*"&E$4&"*")} -> 0 | F10: {=SUMIFS('Input Harian'!$F$5:$F$104, IF('Input Harian'!$B$5:$B$104="", LOOKUP(ROW('Input Harian'!$B$5:$B$104), ROW('Input Harian'!$B$5:$B$104)/('Input Harian'!$B$5:$B$104<>""), 'Input Harian'!$B$5:$B$104), 'Input Harian'!$B$5:$B$104), $B10, 'Input Harian'!$D$5:$D$104,"*Belanja*")} -> 0 | G10: {=SUMIFS('Input Harian'!$F$5:$F$104, IF('Input Harian'!$B$5:$B$104="", LOOKUP(ROW('Input Harian'!$B$5:$B$104), ROW('Input Harian'!$B$5:$B$104)/('Input Harian'!$B$5:$B$104<>""), 'Input Harian'!$B$5:$B$104), 'Input Harian'!$B$5:$B$104), $B10, 'Input Harian'!$D$5:$D$104,"*"&G$4&"*")} -> 0 | H10: {=SUMIFS('Input Harian'!$F$5:$F$104, IF('Input Harian'!$B$5:$B$104="", LOOKUP(ROW('Input Harian'!$B$5:$B$104), ROW('Input Harian'!$B$5:$B$104)/('Input Harian'!$B$5:$B$104<>""), 'Input Harian'!$B$5:$B$104), 'Input Harian'!$B$5:$B$104), $B10, 'Input Harian'!$D$5:$D$104,"*"&H$4&"*")} -> 0 | I10: {=SUMIFS('Input Harian'!$F$5:$F$104, IF('Input Harian'!$B$5:$B$104="", LOOKUP(ROW('Input Harian'!$B$5:$B$104), ROW('Input Harian'!$B$5:$B$104)/('Input Harian'!$B$5:$B$104<>""), 'Input Harian'!$B$5:$B$104), 'Input Harian'!$B$5:$B$104), $B10, 'Input Harian'!$D$5:$D$104,"*"&I$4&"*")} -> 0 | J10: =SUM(D10:I10) -> 27000
B11: 18 | C11: Senin | D11: {=SUMIFS('Input Harian'!$F$5:$F$104, IF('Input Harian'!$B$5:$B$104="", LOOKUP(ROW('Input Harian'!$B$5:$B$104), ROW('Input Harian'!$B$5:$B$104)/('Input Harian'!$B$5:$B$104<>""), 'Input Harian'!$B$5:$B$104), 'Input Harian'!$B$5:$B$104), $B11, 'Input Harian'!$D$5:$D$104,"*"&D$4&"*")} -> 12000 | E11: {=SUMIFS('Input Harian'!$F$5:$F$104, IF('Input Harian'!$B$5:$B$104="", LOOKUP(ROW('Input Harian'!$B$5:$B$104), ROW('Input Harian'!$B$5:$B$104)/('Input Harian'!$B$5:$B$104<>""), 'Input Harian'!$B$5:$B$104), 'Input Harian'!$B$5:$B$104), $B11, 'Input Harian'!$D$5:$D$104,"*"&E$4&"*")} -> 0 | F11: {=SUMIFS('Input Harian'!$F$5:$F$104, IF('Input Harian'!$B$5:$B$104="", LOOKUP(ROW('Input Harian'!$B$5:$B$104), ROW('Input Harian'!$B$5:$B$104)/('Input Harian'!$B$5:$B$104<>""), 'Input Harian'!$B$5:$B$104), 'Input Harian'!$B$5:$B$104), $B11, 'Input Harian'!$D$5:$D$104,"*Belanja*")} -> 0 | G11: {=SUMIFS('Input Harian'!$F$5:$F$104, IF('Input Harian'!$B$5:$B$104="", LOOKUP(ROW('Input Harian'!$B$5:$B$104), ROW('Input Harian'!$B$5:$B$104)/('Input Harian'!$B$5:$B$104<>""), 'Input Harian'!$B$5:$B$104), 'Input Harian'!$B$5:$B$104), $B11, 'Input Harian'!$D$5:$D$104,"*"&G$4&"*")} -> 0 | H11: {=SUMIFS('Input Harian'!$F$5:$F$104, IF('Input Harian'!$B$5:$B$104="", LOOKUP(ROW('Input Harian'!$B$5:$B$104), ROW('Input Harian'!$B$5:$B$104)/('Input Harian'!$B$5:$B$104<>""), 'Input Harian'!$B$5:$B$104), 'Input Harian'!$B$5:$B$104), $B11, 'Input Harian'!$D$5:$D$104,"*"&H$4&"*")} -> 0 | I11: {=SUMIFS('Input Harian'!$F$5:$F$104, IF('Input Harian'!$B$5:$B$104="", LOOKUP(ROW('Input Harian'!$B$5:$B$104), ROW('Input Harian'!$B$5:$B$104)/('Input Harian'!$B$5:$B$104<>""), 'Input Harian'!$B$5:$B$104), 'Input Harian'!$B$5:$B$104), $B11, 'Input Harian'!$D$5:$D$104,"*"&I$4&"*")} -> 0 | J11: =SUM(D11:I11) -> 12000
B12: 19 | C12: Selasa | D12: {=SUMIFS('Input Harian'!$F$5:$F$104, IF('Input Harian'!$B$5:$B$104="", LOOKUP(ROW('Input Harian'!$B$5:$B$104), ROW('Input Harian'!$B$5:$B$104)/('Input Harian'!$B$5:$B$104<>""), 'Input Harian'!$B$5:$B$104), 'Input Harian'!$B$5:$B$104), $B12, 'Input Harian'!$D$5:$D$104,"*"&D$4&"*")} -> 50000 | E12: {=SUMIFS('Input Harian'!$F$5:$F$104, IF('Input Harian'!$B$5:$B$104="", LOOKUP(ROW('Input Harian'!$B$5:$B$104), ROW('Input Harian'!$B$5:$B$104)/('Input Harian'!$B$5:$B$104<>""), 'Input Harian'!$B$5:$B$104), 'Input Harian'!$B$5:$B$104), $B12, 'Input Harian'!$D$5:$D$104,"*"&E$4&"*")} -> 20000 | F12: {=SUMIFS('Input Harian'!$F$5:$F$104, IF('Input Harian'!$B$5:$B$104="", LOOKUP(ROW('Input Harian'!$B$5:$B$104), ROW('Input Harian'!$B$5:$B$104)/('Input Harian'!$B$5:$B$104<>""), 'Input Harian'!$B$5:$B$104), 'Input Harian'!$B$5:$B$104), $B12, 'Input Harian'!$D$5:$D$104,"*Belanja*")} -> 0 | G12: {=SUMIFS('Input Harian'!$F$5:$F$104, IF('Input Harian'!$B$5:$B$104="", LOOKUP(ROW('Input Harian'!$B$5:$B$104), ROW('Input Harian'!$B$5:$B$104)/('Input Harian'!$B$5:$B$104<>""), 'Input Harian'!$B$5:$B$104), 'Input Harian'!$B$5:$B$104), $B12, 'Input Harian'!$D$5:$D$104,"*"&G$4&"*")} -> 38500 | H12: {=SUMIFS('Input Harian'!$F$5:$F$104, IF('Input Harian'!$B$5:$B$104="", LOOKUP(ROW('Input Harian'!$B$5:$B$104), ROW('Input Harian'!$B$5:$B$104)/('Input Harian'!$B$5:$B$104<>""), 'Input Harian'!$B$5:$B$104), 'Input Harian'!$B$5:$B$104), $B12, 'Input Harian'!$D$5:$D$104,"*"&H$4&"*")} -> 0 | I12: {=SUMIFS('Input Harian'!$F$5:$F$104, IF('Input Harian'!$B$5:$B$104="", LOOKUP(ROW('Input Harian'!$B$5:$B$104), ROW('Input Harian'!$B$5:$B$104)/('Input Harian'!$B$5:$B$104<>""), 'Input Harian'!$B$5:$B$104), 'Input Harian'!$B$5:$B$104), $B12, 'Input Harian'!$D$5:$D$104,"*"&I$4&"*")} -> 6000 | J12: =SUM(D12:I12) -> 114500
B13: 20 | C13: Rabu | D13: {=SUMIFS('Input Harian'!$F$5:$F$104, IF('Input Harian'!$B$5:$B$104="", LOOKUP(ROW('Input Harian'!$B$5:$B$104), ROW('Input Harian'!$B$5:$B$104)/('Input Harian'!$B$5:$B$104<>""), 'Input Harian'!$B$5:$B$104), 'Input Harian'!$B$5:$B$104), $B13, 'Input Harian'!$D$5:$D$104,"*"&D$4&"*")} -> 35000 | E13: {=SUMIFS('Input Harian'!$F$5:$F$104, IF('Input Harian'!$B$5:$B$104="", LOOKUP(ROW('Input Harian'!$B$5:$B$104), ROW('Input Harian'!$B$5:$B$104)/('Input Harian'!$B$5:$B$104<>""), 'Input Harian'!$B$5:$B$104), 'Input Harian'!$B$5:$B$104), $B13, 'Input Harian'!$D$5:$D$104,"*"&E$4&"*")} -> 20000 | F13: {=SUMIFS('Input Harian'!$F$5:$F$104, IF('Input Harian'!$B$5:$B$104="", LOOKUP(ROW('Input Harian'!$B$5:$B$104), ROW('Input Harian'!$B$5:$B$104)/('Input Harian'!$B$5:$B$104<>""), 'Input Harian'!$B$5:$B$104), 'Input Harian'!$B$5:$B$104), $B13, 'Input Harian'!$D$5:$D$104,"*Belanja*")} -> 9000 | G13: {=SUMIFS('Input Harian'!$F$5:$F$104, IF('Input Harian'!$B$5:$B$104="", LOOKUP(ROW('Input Harian'!$B$5:$B$104), ROW('Input Harian'!$B$5:$B$104)/('Input Harian'!$B$5:$B$104<>""), 'Input Harian'!$B$5:$B$104), 'Input Harian'!$B$5:$B$104), $B13, 'Input Harian'!$D$5:$D$104,"*"&G$4&"*")} -> 0 | H13: {=SUMIFS('Input Harian'!$F$5:$F$104, IF('Input Harian'!$B$5:$B$104="", LOOKUP(ROW('Input Harian'!$B$5:$B$104), ROW('Input Harian'!$B$5:$B$104)/('Input Harian'!$B$5:$B$104<>""), 'Input Harian'!$B$5:$B$104), 'Input Harian'!$B$5:$B$104), $B13, 'Input Harian'!$D$5:$D$104,"*"&H$4&"*")} -> 0 | I13: {=SUMIFS('Input Harian'!$F$5:$F$104, IF('Input Harian'!$B$5:$B$104="", LOOKUP(ROW('Input Harian'!$B$5:$B$104), ROW('Input Harian'!$B$5:$B$104)/('Input Harian'!$B$5:$B$104<>""), 'Input Harian'!$B$5:$B$104), 'Input Harian'!$B$5:$B$104), $B13, 'Input Harian'!$D$5:$D$104,"*"&I$4&"*")} -> 4000 | J13: =SUM(D13:I13) -> 68000
B14: 21 | C14: Kamis | D14: {=SUMIFS('Input Harian'!$F$5:$F$104, IF('Input Harian'!$B$5:$B$104="", LOOKUP(ROW('Input Harian'!$B$5:$B$104), ROW('Input Harian'!$B$5:$B$104)/('Input Harian'!$B$5:$B$104<>""), 'Input Harian'!$B$5:$B$104), 'Input Harian'!$B$5:$B$104), $B14, 'Input Harian'!$D$5:$D$104,"*"&D$4&"*")} -> 0 | E14: {=SUMIFS('Input Harian'!$F$5:$F$104, IF('Input Harian'!$B$5:$B$104="", LOOKUP(ROW('Input Harian'!$B$5:$B$104), ROW('Input Harian'!$B$5:$B$104)/('Input Harian'!$B$5:$B$104<>""), 'Input Harian'!$B$5:$B$104), 'Input Harian'!$B$5:$B$104), $B14, 'Input Harian'!$D$5:$D$104,"*"&E$4&"*")} -> 0 | F14: {=SUMIFS('Input Harian'!$F$5:$F$104, IF('Input Harian'!$B$5:$B$104="", LOOKUP(ROW('Input Harian'!$B$5:$B$104), ROW('Input Harian'!$B$5:$B$104)/('Input Harian'!$B$5:$B$104<>""), 'Input Harian'!$B$5:$B$104), 'Input Harian'!$B$5:$B$104), $B14, 'Input Harian'!$D$5:$D$104,"*Belanja*")} -> 0 | G14: {=SUMIFS('Input Harian'!$F$5:$F$104, IF('Input Harian'!$B$5:$B$104="", LOOKUP(ROW('Input Harian'!$B$5:$B$104), ROW('Input Harian'!$B$5:$B$104)/('Input Harian'!$B$5:$B$104<>""), 'Input Harian'!$B$5:$B$104), 'Input Harian'!$B$5:$B$104), $B14, 'Input Harian'!$D$5:$D$104,"*"&G$4&"*")} -> 0 | H14: {=SUMIFS('Input Harian'!$F$5:$F$104, IF('Input Harian'!$B$5:$B$104="", LOOKUP(ROW('Input Harian'!$B$5:$B$104), ROW('Input Harian'!$B$5:$B$104)/('Input Harian'!$B$5:$B$104<>""), 'Input Harian'!$B$5:$B$104), 'Input Harian'!$B$5:$B$104), $B14, 'Input Harian'!$D$5:$D$104,"*"&H$4&"*")} -> 0 | I14: {=SUMIFS('Input Harian'!$F$5:$F$104, IF('Input Harian'!$B$5:$B$104="", LOOKUP(ROW('Input Harian'!$B$5:$B$104), ROW('Input Harian'!$B$5:$B$104)/('Input Harian'!$B$5:$B$104<>""), 'Input Harian'!$B$5:$B$104), 'Input Harian'!$B$5:$B$104), $B14, 'Input Harian'!$D$5:$D$104,"*"&I$4&"*")} -> 0 | J14: =SUM(D14:I14) -> 0
B15: 22 | C15: Jumat | D15: {=SUMIFS('Input Harian'!$F$5:$F$104, IF('Input Harian'!$B$5:$B$104="", LOOKUP(ROW('Input Harian'!$B$5:$B$104), ROW('Input Harian'!$B$5:$B$104)/('Input Harian'!$B$5:$B$104<>""), 'Input Harian'!$B$5:$B$104), 'Input Harian'!$B$5:$B$104), $B15, 'Input Harian'!$D$5:$D$104,"*"&D$4&"*")} -> 15000 | E15: {=SUMIFS('Input Harian'!$F$5:$F$104, IF('Input Harian'!$B$5:$B$104="", LOOKUP(ROW('Input Harian'!$B$5:$B$104), ROW('Input Harian'!$B$5:$B$104)/('Input Harian'!$B$5:$B$104<>""), 'Input Harian'!$B$5:$B$104), 'Input Harian'!$B$5:$B$104), $B15, 'Input Harian'!$D$5:$D$104,"*"&E$4&"*")} -> 10000 | F15: {=SUMIFS('Input Harian'!$F$5:$F$104, IF('Input Harian'!$B$5:$B$104="", LOOKUP(ROW('Input Harian'!$B$5:$B$104), ROW('Input Harian'!$B$5:$B$104)/('Input Harian'!$B$5:$B$104<>""), 'Input Harian'!$B$5:$B$104), 'Input Harian'!$B$5:$B$104), $B15, 'Input Harian'!$D$5:$D$104,"*Belanja*")} -> 0 | G15: {=SUMIFS('Input Harian'!$F$5:$F$104, IF('Input Harian'!$B$5:$B$104="", LOOKUP(ROW('Input Harian'!$B$5:$B$104), ROW('Input Harian'!$B$5:$B$104)/('Input Harian'!$B$5:$B$104<>""), 'Input Harian'!$B$5:$B$104), 'Input Harian'!$B$5:$B$104), $B15, 'Input Harian'!$D$5:$D$104,"*"&G$4&"*")} -> 0 | H15: {=SUMIFS('Input Harian'!$F$5:$F$104, IF('Input Harian'!$B$5:$B$104="", LOOKUP(ROW('Input Harian'!$B$5:$B$104), ROW('Input Harian'!$B$5:$B$104)/('Input Harian'!$B$5:$B$104<>""), 'Input Harian'!$B$5:$B$104), 'Input Harian'!$B$5:$B$104), $B15, 'Input Harian'!$D$5:$D$104,"*"&H$4&"*")} -> 0 | I15: {=SUMIFS('Input Harian'!$F$5:$F$104, IF('Input Harian'!$B$5:$B$104="", LOOKUP(ROW('Input Harian'!$B$5:$B$104), ROW('Input Harian'!$B$5:$B$104)/('Input Harian'!$B$5:$B$104<>""), 'Input Harian'!$B$5:$B$104), 'Input Harian'!$B$5:$B$104), $B15, 'Input Harian'!$D$5:$D$104,"*"&I$4&"*")} -> 2000 | J15: =SUM(D15:I15) -> 27000
B16: 23 | C16: Sabtu | D16: {=SUMIFS('Input Harian'!$F$5:$F$104, IF('Input Harian'!$B$5:$B$104="", LOOKUP(ROW('Input Harian'!$B$5:$B$104), ROW('Input Harian'!$B$5:$B$104)/('Input Harian'!$B$5:$B$104<>""), 'Input Harian'!$B$5:$B$104), 'Input Harian'!$B$5:$B$104), $B16, 'Input Harian'!$D$5:$D$104,"*"&D$4&"*")} -> 4000 | E16: {=SUMIFS('Input Harian'!$F$5:$F$104, IF('Input Harian'!$B$5:$B$104="", LOOKUP(ROW('Input Harian'!$B$5:$B$104), ROW('Input Harian'!$B$5:$B$104)/('Input Harian'!$B$5:$B$104<>""), 'Input Harian'!$B$5:$B$104), 'Input Harian'!$B$5:$B$104), $B16, 'Input Harian'!$D$5:$D$104,"*"&E$4&"*")} -> 0 | F16: {=SUMIFS('Input Harian'!$F$5:$F$104, IF('Input Harian'!$B$5:$B$104="", LOOKUP(ROW('Input Harian'!$B$5:$B$104), ROW('Input Harian'!$B$5:$B$104)/('Input Harian'!$B$5:$B$104<>""), 'Input Harian'!$B$5:$B$104), 'Input Harian'!$B$5:$B$104), $B16, 'Input Harian'!$D$5:$D$104,"*Belanja*")} -> 0 | G16: {=SUMIFS('Input Harian'!$F$5:$F$104, IF('Input Harian'!$B$5:$B$104="", LOOKUP(ROW('Input Harian'!$B$5:$B$104), ROW('Input Harian'!$B$5:$B$104)/('Input Harian'!$B$5:$B$104<>""), 'Input Harian'!$B$5:$B$104), 'Input Harian'!$B$5:$B$104), $B16, 'Input Harian'!$D$5:$D$104,"*"&G$4&"*")} -> 0 | H16: {=SUMIFS('Input Harian'!$F$5:$F$104, IF('Input Harian'!$B$5:$B$104="", LOOKUP(ROW('Input Harian'!$B$5:$B$104), ROW('Input Harian'!$B$5:$B$104)/('Input Harian'!$B$5:$B$104<>""), 'Input Harian'!$B$5:$B$104), 'Input Harian'!$B$5:$B$104), $B16, 'Input Harian'!$D$5:$D$104,"*"&H$4&"*")} -> 0 | I16: {=SUMIFS('Input Harian'!$F$5:$F$104, IF('Input Harian'!$B$5:$B$104="", LOOKUP(ROW('Input Harian'!$B$5:$B$104), ROW('Input Harian'!$B$5:$B$104)/('Input Harian'!$B$5:$B$104<>""), 'Input Harian'!$B$5:$B$104), 'Input Harian'!$B$5:$B$104), $B16, 'Input Harian'!$D$5:$D$104,"*"&I$4&"*")} -> 0 | J16: =SUM(D16:I16) -> 4000
B17: 24 | C17: Minggu | D17: {=SUMIFS('Input Harian'!$F$5:$F$104, IF('Input Harian'!$B$5:$B$104="", LOOKUP(ROW('Input Harian'!$B$5:$B$104), ROW('Input Harian'!$B$5:$B$104)/('Input Harian'!$B$5:$B$104<>""), 'Input Harian'!$B$5:$B$104), 'Input Harian'!$B$5:$B$104), $B17, 'Input Harian'!$D$5:$D$104,"*"&D$4&"*")} -> 47000 | E17: {=SUMIFS('Input Harian'!$F$5:$F$104, IF('Input Harian'!$B$5:$B$104="", LOOKUP(ROW('Input Harian'!$B$5:$B$104), ROW('Input Harian'!$B$5:$B$104)/('Input Harian'!$B$5:$B$104<>""), 'Input Harian'!$B$5:$B$104), 'Input Harian'!$B$5:$B$104), $B17, 'Input Harian'!$D$5:$D$104,"*"&E$4&"*")} -> 20000 | F17: {=SUMIFS('Input Harian'!$F$5:$F$104, IF('Input Harian'!$B$5:$B$104="", LOOKUP(ROW('Input Harian'!$B$5:$B$104), ROW('Input Harian'!$B$5:$B$104)/('Input Harian'!$B$5:$B$104<>""), 'Input Harian'!$B$5:$B$104), 'Input Harian'!$B$5:$B$104), $B17, 'Input Harian'!$D$5:$D$104,"*Belanja*")} -> 0 | G17: {=SUMIFS('Input Harian'!$F$5:$F$104, IF('Input Harian'!$B$5:$B$104="", LOOKUP(ROW('Input Harian'!$B$5:$B$104), ROW('Input Harian'!$B$5:$B$104)/('Input Harian'!$B$5:$B$104<>""), 'Input Harian'!$B$5:$B$104), 'Input Harian'!$B$5:$B$104), $B17, 'Input Harian'!$D$5:$D$104,"*"&G$4&"*")} -> 0 | H17: {=SUMIFS('Input Harian'!$F$5:$F$104, IF('Input Harian'!$B$5:$B$104="", LOOKUP(ROW('Input Harian'!$B$5:$B$104), ROW('Input Harian'!$B$5:$B$104)/('Input Harian'!$B$5:$B$104<>""), 'Input Harian'!$B$5:$B$104), 'Input Harian'!$B$5:$B$104), $B17, 'Input Harian'!$D$5:$D$104,"*"&H$4&"*")} -> 0 | I17: {=SUMIFS('Input Harian'!$F$5:$F$104, IF('Input Harian'!$B$5:$B$104="", LOOKUP(ROW('Input Harian'!$B$5:$B$104), ROW('Input Harian'!$B$5:$B$104)/('Input Harian'!$B$5:$B$104<>""), 'Input Harian'!$B$5:$B$104), 'Input Harian'!$B$5:$B$104), $B17, 'Input Harian'!$D$5:$D$104,"*"&I$4&"*")} -> 4000 | J17: =SUM(D17:I17) -> 71000
B18: 25 | C18: Senin | D18: {=SUMIFS('Input Harian'!$F$5:$F$104, IF('Input Harian'!$B$5:$B$104="", LOOKUP(ROW('Input Harian'!$B$5:$B$104), ROW('Input Harian'!$B$5:$B$104)/('Input Harian'!$B$5:$B$104<>""), 'Input Harian'!$B$5:$B$104), 'Input Harian'!$B$5:$B$104), $B18, 'Input Harian'!$D$5:$D$104,"*"&D$4&"*")} -> 35000 | E18: {=SUMIFS('Input Harian'!$F$5:$F$104, IF('Input Harian'!$B$5:$B$104="", LOOKUP(ROW('Input Harian'!$B$5:$B$104), ROW('Input Harian'!$B$5:$B$104)/('Input Harian'!$B$5:$B$104<>""), 'Input Harian'!$B$5:$B$104), 'Input Harian'!$B$5:$B$104), $B18, 'Input Harian'!$D$5:$D$104,"*"&E$4&"*")} -> 10000 | F18: {=SUMIFS('Input Harian'!$F$5:$F$104, IF('Input Harian'!$B$5:$B$104="", LOOKUP(ROW('Input Harian'!$B$5:$B$104), ROW('Input Harian'!$B$5:$B$104)/('Input Harian'!$B$5:$B$104<>""), 'Input Harian'!$B$5:$B$104), 'Input Harian'!$B$5:$B$104), $B18, 'Input Harian'!$D$5:$D$104,"*Belanja*")} -> 0 | G18: {=SUMIFS('Input Harian'!$F$5:$F$104, IF('Input Harian'!$B$5:$B$104="", LOOKUP(ROW('Input Harian'!$B$5:$B$104), ROW('Input Harian'!$B$5:$B$104)/('Input Harian'!$B$5:$B$104<>""), 'Input Harian'!$B$5:$B$104), 'Input Harian'!$B$5:$B$104), $B18, 'Input Harian'!$D$5:$D$104,"*"&G$4&"*")} -> 0 | H18: {=SUMIFS('Input Harian'!$F$5:$F$104, IF('Input Harian'!$B$5:$B$104="", LOOKUP(ROW('Input Harian'!$B$5:$B$104), ROW('Input Harian'!$B$5:$B$104)/('Input Harian'!$B$5:$B$104<>""), 'Input Harian'!$B$5:$B$104), 'Input Harian'!$B$5:$B$104), $B18, 'Input Harian'!$D$5:$D$104,"*"&H$4&"*")} -> 0 | I18: {=SUMIFS('Input Harian'!$F$5:$F$104, IF('Input Harian'!$B$5:$B$104="", LOOKUP(ROW('Input Harian'!$B$5:$B$104), ROW('Input Harian'!$B$5:$B$104)/('Input Harian'!$B$5:$B$104<>""), 'Input Harian'!$B$5:$B$104), 'Input Harian'!$B$5:$B$104), $B18, 'Input Harian'!$D$5:$D$104,"*"&I$4&"*")} -> 4000 | J18: =SUM(D18:I18) -> 49000
B19: 26 | C19: Selasa | D19: {=SUMIFS('Input Harian'!$F$5:$F$104, IF('Input Harian'!$B$5:$B$104="", LOOKUP(ROW('Input Harian'!$B$5:$B$104), ROW('Input Harian'!$B$5:$B$104)/('Input Harian'!$B$5:$B$104<>""), 'Input Harian'!$B$5:$B$104), 'Input Harian'!$B$5:$B$104), $B19, 'Input Harian'!$D$5:$D$104,"*"&D$4&"*")} -> 25000 | E19: {=SUMIFS('Input Harian'!$F$5:$F$104, IF('Input Harian'!$B$5:$B$104="", LOOKUP(ROW('Input Harian'!$B$5:$B$104), ROW('Input Harian'!$B$5:$B$104)/('Input Harian'!$B$5:$B$104<>""), 'Input Harian'!$B$5:$B$104), 'Input Harian'!$B$5:$B$104), $B19, 'Input Harian'!$D$5:$D$104,"*"&E$4&"*")} -> 10000 | F19: {=SUMIFS('Input Harian'!$F$5:$F$104, IF('Input Harian'!$B$5:$B$104="", LOOKUP(ROW('Input Harian'!$B$5:$B$104), ROW('Input Harian'!$B$5:$B$104)/('Input Harian'!$B$5:$B$104<>""), 'Input Harian'!$B$5:$B$104), 'Input Harian'!$B$5:$B$104), $B19, 'Input Harian'!$D$5:$D$104,"*Belanja*")} -> 0 | G19: {=SUMIFS('Input Harian'!$F$5:$F$104, IF('Input Harian'!$B$5:$B$104="", LOOKUP(ROW('Input Harian'!$B$5:$B$104), ROW('Input Harian'!$B$5:$B$104)/('Input Harian'!$B$5:$B$104<>""), 'Input Harian'!$B$5:$B$104), 'Input Harian'!$B$5:$B$104), $B19, 'Input Harian'!$D$5:$D$104,"*"&G$4&"*")} -> 0 | H19: {=SUMIFS('Input Harian'!$F$5:$F$104, IF('Input Harian'!$B$5:$B$104="", LOOKUP(ROW('Input Harian'!$B$5:$B$104), ROW('Input Harian'!$B$5:$B$104)/('Input Harian'!$B$5:$B$104<>""), 'Input Harian'!$B$5:$B$104), 'Input Harian'!$B$5:$B$104), $B19, 'Input Harian'!$D$5:$D$104,"*"&H$4&"*")} -> 0 | I19: {=SUMIFS('Input Harian'!$F$5:$F$104, IF('Input Harian'!$B$5:$B$104="", LOOKUP(ROW('Input Harian'!$B$5:$B$104), ROW('Input Harian'!$B$5:$B$104)/('Input Harian'!$B$5:$B$104<>""), 'Input Harian'!$B$5:$B$104), 'Input Harian'!$B$5:$B$104), $B19, 'Input Harian'!$D$5:$D$104,"*"&I$4&"*")} -> 50000 | J19: =SUM(D19:I19) -> 85000
... B24: 31 | C24: Minggu | D24: {=SUMIFS('Input Harian'!$F$5:$F$104, IF('Input Harian'!$B$5:$B$104="", LOOKUP(ROW('Input Harian'!$B$5:$B$104), ROW('Input Harian'!$B$5:$B$104)/('Input Harian'!$B$5:$B$104<>""), 'Input Harian'!$B$5:$B$104), 'Input Harian'!$B$5:$B$104), $B24, 'Input Harian'!$D$5:$D$104,"*"&D$4&"*")} -> 0 | E24: {=SUMIFS('Input Harian'!$F$5:$F$104, IF('Input Harian'!$B$5:$B$104="", LOOKUP(ROW('Input Harian'!$B$5:$B$104), ROW('Input Harian'!$B$5:$B$104)/('Input Harian'!$B$5:$B$104<>""), 'Input Harian'!$B$5:$B$104), 'Input Harian'!$B$5:$B$104), $B24, 'Input Harian'!$D$5:$D$104,"*"&E$4&"*")} -> 20000 | F24: {=SUMIFS('Input Harian'!$F$5:$F$104, IF('Input Harian'!$B$5:$B$104="", LOOKUP(ROW('Input Harian'!$B$5:$B$104), ROW('Input Harian'!$B$5:$B$104)/('Input Harian'!$B$5:$B$104<>""), 'Input Harian'!$B$5:$B$104), 'Input Harian'!$B$5:$B$104), $B24, 'Input Harian'!$D$5:$D$104,"*Belanja*")} -> 0 | G24: {=SUMIFS('Input Harian'!$F$5:$F$104, IF('Input Harian'!$B$5:$B$104="", LOOKUP(ROW('Input Harian'!$B$5:$B$104), ROW('Input Harian'!$B$5:$B$104)/('Input Harian'!$B$5:$B$104<>""), 'Input Harian'!$B$5:$B$104), 'Input Harian'!$B$5:$B$104), $B24, 'Input Harian'!$D$5:$D$104,"*"&G$4&"*")} -> 0 | H24: {=SUMIFS('Input Harian'!$F$5:$F$104, IF('Input Harian'!$B$5:$B$104="", LOOKUP(ROW('Input Harian'!$B$5:$B$104), ROW('Input Harian'!$B$5:$B$104)/('Input Harian'!$B$5:$B$104<>""), 'Input Harian'!$B$5:$B$104), 'Input Harian'!$B$5:$B$104), $B24, 'Input Harian'!$D$5:$D$104,"*"&H$4&"*")} -> 0 | I24: {=SUMIFS('Input Harian'!$F$5:$F$104, IF('Input Harian'!$B$5:$B$104="", LOOKUP(ROW('Input Harian'!$B$5:$B$104), ROW('Input Harian'!$B$5:$B$104)/('Input Harian'!$B$5:$B$104<>""), 'Input Harian'!$B$5:$B$104), 'Input Harian'!$B$5:$B$104), $B24, 'Input Harian'!$D$5:$D$104,"*"&I$4&"*")} -> 0 | J24: =SUM(D24:I24) -> 20000
B25: TOTAL | D25: =SUM(D5:D24) -> 347000 | E25: =SUM(E5:E24) -> 169000 | F25: =SUM(F5:F24) -> 9000 | G25: =SUM(G5:G24) -> 38500 | H25: =SUM(H5:H24) -> 0 | I25: =SUM(I5:I24) -> 71000 | J25: =SUM(J5:J24) -> 634500
B26: RATA-RATA/HARI | D26: =D25/20 -> 17350 | E26: =E25/20 -> 8450 | F26: =F25/20 -> 450 | G26: =G25/20 -> 1925 | H26: =H25/20 -> 0 | I26: =I25/20 -> 3550 | J26: =J25/20 -> 31725

Sheet Analisis Kategori
B2: ANALISIS PENGELUARAN PER KATEGORI - APRIL 2026
B4: Kategori | C4: Total (Rp) | D4: % dari Total | E4: Rata-rata/Hari | F4: Transaksi
B5: Makanan | C5: ='Rekap Harian'!D25 -> 347000 | D5: =IF($C$11=0,0,C5/$C$11) -> 0.54688731 | E5: =C5/18 -> 19277.778 | F5: =COUNTIFS('Input Harian'!$D$5:$D$104,"Makanan",'Input Harian'!$F$5:$F$104,">0") -> 18
B6: Transportasi | C6: ='Rekap Harian'!E25 -> 169000 | D6: =IF($C$11=0,0,C6/$C$11) -> 0.26635146 | E6: =C6/18 -> 9388.8889 | F6: =COUNTIFS('Input Harian'!$D$5:$D$104,"Transportasi",'Input Harian'!$F$5:$F$104,">0") -> 10
B7: Belanja | C7: ='Rekap Harian'!F25 -> 9000 | D7: =IF($C$11=0,0,C7/$C$11) -> 0.014184397 | E7: =C7/30 -> 300 | F7: =COUNTIFS('Input Harian'!$D$5:$D$104,"Belanja",'Input Harian'!$F$5:$F$104,">0") -> 1
B8: Hiburan | C8: ='Rekap Harian'!G25 -> 38500 | D8: =IF($C$11=0,0,C8/$C$11) -> 0.060677699 | E8: =C8/30 -> 1283.3333 | F8: =COUNTIFS('Input Harian'!$D$5:$D$104,"Hiburan",'Input Harian'!$F$5:$F$104,">0") -> 2
B9: Tagihan (Listrik/Air/Internet) | C9: ='Rekap Harian'!H25 -> 0 | D9: =IF($C$11=0,0,C9/$C$11) -> 0 | E9: =C9/30 -> 0 | F9: =COUNTIFS('Input Harian'!$D$5:$D$104,"Tagihan (Listrik/Air/Internet)",'Input Harian'!$F$5:$F$104,">0") -> 0
B10: Lainnya | C10: ='Rekap Harian'!I25 -> 71000 | D10: =IF($C$11=0,0,C10/$C$11) -> 0.11189913 | E10: =C10/30 -> 2366.6667 | F10: =COUNTIFS('Input Harian'!$D$5:$D$104,"Lainnya",'Input Harian'!$F$5:$F$104,">0") -> 9
B11: TOTAL | C11: =SUM(C5:C10) -> 634500 | D11: 100.0% | E11: =SUM(E5:E10) -> 32616.667 | F11: =SUM(F5:F10) -> 40
B14: BUDGET vs AKTUAL
B15: Kategori | C15: Budget (Rp) | D15: Aktual (Rp) | E15: Selisih (Rp) | F15: % Tercapai
B16: Makanan | C16: 300000 | D16: =C5 -> 347000 | E16: =C16-D16 -> -47000 | F16: =IF(C16=0,0,D16/C16) -> 1.1566667
B17: Transportasi | C17: 300000 | D17: =C6 -> 169000 | E17: =C17-D17 -> 131000 | F17: =IF(C17=0,0,D17/C17) -> 0.56333333
B18: Belanja | C18: 0 | D18: =C7 -> 9000 | E18: =C18-D18 -> -9000 | F18: =IF(C18=0,0,D18/C18) -> 0
B19: Hiburan | C19: 100000 | D19: =C8 -> 38500 | E19: =C19-D19 -> 61500 | F19: =IF(C19=0,0,D19/C19) -> 0.385
B20: Tagihan (Listrik/Air/Internet) | C20: 0 | D20: =C9 -> 0 | E20: =C20-D20 -> 0 | F20: =IF(C20=0,0,D20/C20) -> 0
B21: Lainnya | C21: 20000 | D21: =C10 -> 71000 | E21: =C21-D21 -> -51000 | F21: =IF(C21=0,0,D21/C21) -> 3.55
B22: TOTAL | C22: =SUM(C16:C21) -> 720000 | D22: =SUM(D16:D21) -> 634500 | E22: =SUM(E16:E21) -> 85500 | F22: =SUM(F16:F21) -> 5.655

Sheet Grafik
B2: VISUALISASI PENGELUARAN - APRIL 2026
B4: Visual 1 | N4: Visual 2
B26: Visual 3
